<?xml version="1.0" encoding="UTF-8"?>
<testng-results skipped="0" failed="2" ignored="0" total="2" passed="0">
  <reporter-output>
  </reporter-output>
  <suite name="Default suite" duration-ms="95901" started-at="2021-03-03T11:44:05 IST" finished-at="2021-03-03T11:45:41 IST">
    <groups>
    </groups>
    <test name="Default test" duration-ms="95901" started-at="2021-03-03T11:44:05 IST" finished-at="2021-03-03T11:45:41 IST">
      <class name="testcase.ShopifyStartFreeTrialTest">
        <test-method status="FAIL" signature="testOne()[pri:0, instance:testcase.ShopifyStartFreeTrialTest@3d8314f0]" name="testOne" duration-ms="14608" started-at="2021-03-03T11:44:05 IST" finished-at="2021-03-03T11:44:19 IST">
          <exception class="java.lang.AssertionError">
            <message>
              <![CDATA[Please enter a store name]]>
            </message>
            <full-stacktrace>
              <![CDATA[java.lang.AssertionError: Please enter a store name
at org.testng.Assert.fail(Assert.java:99)
at tekstack.StoreNameMandatoryCheck.base.BaseUI.reportFail(BaseUI.java:162)
at tekstack.StoreNameMandatoryCheck.base.BaseUI.findError(BaseUI.java:203)
at testcase.ShopifyStartFreeTrialTest.testOne(ShopifyStartFreeTrialTest.java:20)
at sun.reflect.NativeMethodAccessorImpl.invoke0(Native Method)
at sun.reflect.NativeMethodAccessorImpl.invoke(Unknown Source)
at sun.reflect.DelegatingMethodAccessorImpl.invoke(Unknown Source)
at java.lang.reflect.Method.invoke(Unknown Source)
at org.testng.internal.MethodInvocationHelper.invokeMethod(MethodInvocationHelper.java:132)
at org.testng.internal.TestInvoker.invokeMethod(TestInvoker.java:599)
at org.testng.internal.TestInvoker.invokeTestMethod(TestInvoker.java:174)
at org.testng.internal.MethodRunner.runInSequence(MethodRunner.java:46)
at org.testng.internal.TestInvoker$MethodInvocationAgent.invoke(TestInvoker.java:822)
at org.testng.internal.TestInvoker.invokeTestMethods(TestInvoker.java:147)
at org.testng.internal.TestMethodWorker.invokeTestMethods(TestMethodWorker.java:146)
at org.testng.internal.TestMethodWorker.run(TestMethodWorker.java:128)
at java.util.ArrayList.forEach(Unknown Source)
at org.testng.TestRunner.privateRun(TestRunner.java:764)
at org.testng.TestRunner.run(TestRunner.java:585)
at org.testng.SuiteRunner.runTest(SuiteRunner.java:384)
at org.testng.SuiteRunner.runSequentially(SuiteRunner.java:378)
at org.testng.SuiteRunner.privateRun(SuiteRunner.java:337)
at org.testng.SuiteRunner.run(SuiteRunner.java:286)
at org.testng.SuiteRunnerWorker.runSuite(SuiteRunnerWorker.java:53)
at org.testng.SuiteRunnerWorker.run(SuiteRunnerWorker.java:96)
at org.testng.TestNG.runSuitesSequentially(TestNG.java:1218)
at org.testng.TestNG.runSuitesLocally(TestNG.java:1140)
at org.testng.TestNG.runSuites(TestNG.java:1069)
at org.testng.TestNG.run(TestNG.java:1037)
at org.testng.remote.AbstractRemoteTestNG.run(AbstractRemoteTestNG.java:115)
at org.testng.remote.RemoteTestNG.initAndRun(RemoteTestNG.java:251)
at org.testng.remote.RemoteTestNG.main(RemoteTestNG.java:77)
]]>
            </full-stacktrace>
          </exception> <!-- java.lang.AssertionError -->
          <reporter-output>
          </reporter-output>
        </test-method> <!-- testOne -->
        <test-method status="PASS" signature="afterTest()[pri:0, instance:testcase.ShopifyStartFreeTrialTest@3d8314f0]" name="afterTest" is-config="true" duration-ms="861" started-at="2021-03-03T11:44:19 IST" finished-at="2021-03-03T11:44:20 IST">
          <reporter-output>
          </reporter-output>
        </test-method> <!-- afterTest -->
        <test-method status="FAIL" signature="testTwo()[pri:0, instance:testcase.ShopifyStartFreeTrialTest@3d8314f0]" name="testTwo" duration-ms="76172" started-at="2021-03-03T11:44:20 IST" finished-at="2021-03-03T11:45:36 IST">
          <exception class="java.lang.AssertionError">
            <message>
              <![CDATA[Please enter a store name]]>
            </message>
            <full-stacktrace>
              <![CDATA[java.lang.AssertionError: Please enter a store name
at org.testng.Assert.fail(Assert.java:99)
at tekstack.StoreNameMandatoryCheck.base.BaseUI.reportFail(BaseUI.java:162)
at tekstack.StoreNameMandatoryCheck.base.BaseUI.findError(BaseUI.java:203)
at testcase.ShopifyStartFreeTrialTest.testTwo(ShopifyStartFreeTrialTest.java:34)
at sun.reflect.NativeMethodAccessorImpl.invoke0(Native Method)
at sun.reflect.NativeMethodAccessorImpl.invoke(Unknown Source)
at sun.reflect.DelegatingMethodAccessorImpl.invoke(Unknown Source)
at java.lang.reflect.Method.invoke(Unknown Source)
at org.testng.internal.MethodInvocationHelper.invokeMethod(MethodInvocationHelper.java:132)
at org.testng.internal.TestInvoker.invokeMethod(TestInvoker.java:599)
at org.testng.internal.TestInvoker.invokeTestMethod(TestInvoker.java:174)
at org.testng.internal.MethodRunner.runInSequence(MethodRunner.java:46)
at org.testng.internal.TestInvoker$MethodInvocationAgent.invoke(TestInvoker.java:822)
at org.testng.internal.TestInvoker.invokeTestMethods(TestInvoker.java:147)
at org.testng.internal.TestMethodWorker.invokeTestMethods(TestMethodWorker.java:146)
at org.testng.internal.TestMethodWorker.run(TestMethodWorker.java:128)
at java.util.ArrayList.forEach(Unknown Source)
at org.testng.TestRunner.privateRun(TestRunner.java:764)
at org.testng.TestRunner.run(TestRunner.java:585)
at org.testng.SuiteRunner.runTest(SuiteRunner.java:384)
at org.testng.SuiteRunner.runSequentially(SuiteRunner.java:378)
at org.testng.SuiteRunner.privateRun(SuiteRunner.java:337)
at org.testng.SuiteRunner.run(SuiteRunner.java:286)
at org.testng.SuiteRunnerWorker.runSuite(SuiteRunnerWorker.java:53)
at org.testng.SuiteRunnerWorker.run(SuiteRunnerWorker.java:96)
at org.testng.TestNG.runSuitesSequentially(TestNG.java:1218)
at org.testng.TestNG.runSuitesLocally(TestNG.java:1140)
at org.testng.TestNG.runSuites(TestNG.java:1069)
at org.testng.TestNG.run(TestNG.java:1037)
at org.testng.remote.AbstractRemoteTestNG.run(AbstractRemoteTestNG.java:115)
at org.testng.remote.RemoteTestNG.initAndRun(RemoteTestNG.java:251)
at org.testng.remote.RemoteTestNG.main(RemoteTestNG.java:77)
]]>
            </full-stacktrace>
          </exception> <!-- java.lang.AssertionError -->
          <reporter-output>
          </reporter-output>
        </test-method> <!-- testTwo -->
        <test-method status="PASS" signature="afterTest()[pri:0, instance:testcase.ShopifyStartFreeTrialTest@3d8314f0]" name="afterTest" is-config="true" duration-ms="3426" started-at="2021-03-03T11:45:36 IST" finished-at="2021-03-03T11:45:40 IST">
          <reporter-output>
          </reporter-output>
        </test-method> <!-- afterTest -->
        <test-method status="PASS" signature="endReport()[pri:0, instance:testcase.ShopifyStartFreeTrialTest@3d8314f0]" name="endReport" is-config="true" duration-ms="730" started-at="2021-03-03T11:45:40 IST" finished-at="2021-03-03T11:45:41 IST">
          <reporter-output>
          </reporter-output>
        </test-method> <!-- endReport -->
      </class> <!-- testcase.ShopifyStartFreeTrialTest -->
    </test> <!-- Default test -->
  </suite> <!-- Default suite -->
</testng-results>
